Workbook

Sheet 毛立新
A1: ='[1]特别隐藏版（勿动、勿看）'!A1 -> 2026年度WB进度 | B1: ='[1]特别隐藏版（勿动、勿看）'!B1 -> 0 | C1: ='[1]特别隐藏版（勿动、勿看）'!C1 -> 0 | D1: ='[1]特别隐藏版（勿动、勿看）'!D1 -> 0 | E1: ='[1]特别隐藏版（勿动、勿看）'!E1 -> 0 | F1: ='[1]特别隐藏版（勿动、勿看）'!F1 -> 0 | G1: ='[1]特别隐藏版（勿动、勿看）'!G1 -> 0 | H1: ='[1]特别隐藏版（勿动、勿看）'!H1 -> 0 | ... O1: ='[1]特别隐藏版（勿动、勿看）'!O1 -> 0
A2: ='[1]特别隐藏版（勿动、勿看）'!A2 -> 项目 | B2: ='[1]特别隐藏版（勿动、勿看）'!B2 -> 月度 | C2: ='[1]特别隐藏版（勿动、勿看）'!C2 -> 2月 | D2: ='[1]特别隐藏版（勿动、勿看）'!D2 -> 3月 | E2: ='[1]特别隐藏版（勿动、勿看）'!E2 -> 4月 | F2: ='[1]特别隐藏版（勿动、勿看）'!F2 -> 5月 | G2: ='[1]特别隐藏版（勿动、勿看）'!G2 -> 6月 | H2: ='[1]特别隐藏版（勿动、勿看）'!H2 -> 7月 | ... O2: ='[1]特别隐藏版（勿动、勿看）'!O2 -> 汇总
A3: ='[1]特别隐藏版（勿动、勿看）'!A3 -> 0 | B3: ='[1]特别隐藏版（勿动、勿看）'!B3 -> 季度 | C3: ='[1]特别隐藏版（勿动、勿看）'!C3 -> Q1 | D3: ='[1]特别隐藏版（勿动、勿看）'!D3 -> 0 | E3: ='[1]特别隐藏版（勿动、勿看）'!E3 -> 0 | F3: ='[1]特别隐藏版（勿动、勿看）'!F3 -> Q2 | G3: ='[1]特别隐藏版（勿动、勿看）'!G3 -> 0 | H3: ='[1]特别隐藏版（勿动、勿看）'!H3 -> 0 | ... O3: ='[1]特别隐藏版（勿动、勿看）'!O3 -> 0
A4: ='[1]特别隐藏版（勿动、勿看）'!A4 -> 0 | B4: ='[1]特别隐藏版（勿动、勿看）'!B4 -> 季度财报 | C4: ='[1]2026年度男装汇总分析'!C4 -> 935295.04 | D4: ='[1]特别隐藏版（勿动、勿看）'!D4 -> 0 | E4: ='[1]特别隐藏版（勿动、勿看）'!E4 -> 0 | F4: ='[1]2026年度男装汇总分析'!F4 -> 636263.83 | G4: ='[1]特别隐藏版（勿动、勿看）'!G4 -> 0 | H4: ='[1]特别隐藏版（勿动、勿看）'!H4 -> 0 | I4: ='[1]2026年度男装汇总分析'!I4 -> 0 | J4: ='[1]特别隐藏版（勿动、勿看）'!J4 -> 0 | K4: ='[1]特别隐藏版（勿动、勿看）'!K4 -> 0 | L4: ='[1]2026年度男装汇总分析'!L4 -> 0 | M4: ='[1]特别隐藏版（勿动、勿看）'!M4 -> 0 | N4: ='[1]特别隐藏版（勿动、勿看）'!N4 -> 0 | O4: ='[1]特别隐藏版（勿动、勿看）'!O4 -> 0
A5: ='[1]特别隐藏版（勿动、勿看）'!A5 -> 0 | B5: ='[1]特别隐藏版（勿动、勿看）'!B5 -> 季度财报进度 | C5: ='[1]2026年度男装汇总分析'!C5 -> 0.72521594 | D5: ='[1]特别隐藏版（勿动、勿看）'!D5 -> 0 | E5: ='[1]特别隐藏版（勿动、勿看）'!E5 -> 0 | F5: ='[1]2026年度男装汇总分析'!F5 -> 0.38256419 | G5: ='[1]特别隐藏版（勿动、勿看）'!G5 -> 0 | H5: ='[1]特别隐藏版（勿动、勿看）'!H5 -> 0 | I5: ='[1]2026年度男装汇总分析'!I5 -> 0 | J5: ='[1]特别隐藏版（勿动、勿看）'!J5 -> 0 | K5: ='[1]特别隐藏版（勿动、勿看）'!K5 -> 0 | L5: ='[1]2026年度男装汇总分析'!L5 -> 0 | M5: ='[1]特别隐藏版（勿动、勿看）'!M5 -> 0 | N5: ='[1]特别隐藏版（勿动、勿看）'!N5 -> 0 | O5: ='[1]特别隐藏版（勿动、勿看）'!O5 -> 0
A6: ='[1]特别隐藏版（勿动、勿看）'!A6 -> 目标完成情况 | B6: ='[1]特别隐藏版（勿动、勿看）'!B6 -> 月度目标 利润（人民币） | C6: ='[1]2026年度男装汇总分析'!C6 -> 335792.79 | D6: ='[1]2026年度男装汇总分析'!D6 -> 495821.97 | E6: ='[1]2026年度男装汇总分析'!E6 -> 546265.88 | F6: ='[1]2026年度男装汇总分析'!F6 -> 614961.36 | G6: ='[1]2026年度男装汇总分析'!G6 -> 531399.52 | H6: ='[1]2026年度男装汇总分析'!H6 -> 549112.84 | I6: ='[1]2026年度男装汇总分析'!I6 -> 691873.25 | J6: ='[1]2026年度男装汇总分析'!J6 -> 669554.76 | ... N6: ='[1]2026年度男装汇总分析'!N6 -> 358899.96 | O6: =SUM(C6:N6) -> 6719999.8
A7: ='[1]特别隐藏版（勿动、勿看）'!A7 -> 0 | B7: ='[1]特别隐藏版（勿动、勿看）'!B7 -> 实际利润（人民币） | C7: ='[1]2026年度男装汇总分析'!C7 -> 301715.93 | D7: ='[1]2026年度男装汇总分析'!D7 -> 484842.75 | E7: ='[1]2026年度男装汇总分析'!E7 -> 148736.36 | F7: ='[1]2026年度男装汇总分析'!F7 -> 284968.47 | G7: ='[1]2026年度男装汇总分析'!G7 -> 269170.2 | H7: ='[1]2026年度男装汇总分析'!H7 -> 82125.154 | I7: ='[1]2026年度男装汇总分析'!I7 -> 0 | J7: ='[1]2026年度男装汇总分析'!J7 -> 0 | ... N7: ='[1]2026年度男装汇总分析'!N7 -> 0 | O7: =SUM(C7:N7) -> 1571558.9
A8: ='[1]特别隐藏版（勿动、勿看）'!A8 -> 0 | B8: ='[1]特别隐藏版（勿动、勿看）'!B8 -> 目标完成进度 | C8: =C7/C6 -> 0.89851818 | D8: =D7/D6 -> 0.97785653 | E8: =E7/E6 -> 0.27227833 | F8: =F7/F6 -> 0.46339248 | G8: =G7/G6 -> 0.50653076 | H8: =H7/H6 -> 0.14955971 | I8: =I7/I6 -> 0 | J8: =J7/J6 -> 0 | ... O8: =O7/O6 -> 0.23386293
A9: ='[1]特别隐藏版（勿动、勿看）'!A9 -> 0 | B9: ='[1]特别隐藏版（勿动、勿看）'!B9 -> 0 | C9: ='[1]特别隐藏版（勿动、勿看）'!C9 -> 0 | D9: ='[1]特别隐藏版（勿动、勿看）'!D9 -> 0 | E9: ='[1]特别隐藏版（勿动、勿看）'!E9 -> 0 | F9: ='[1]特别隐藏版（勿动、勿看）'!F9 -> 0 | G9: ='[1]特别隐藏版（勿动、勿看）'!G9 -> 0 | H9: ='[1]特别隐藏版（勿动、勿看）'!H9 -> 0 | ... O9: ='[1]特别隐藏版（勿动、勿看）'!O9 -> 0
A10: ='[1]特别隐藏版（勿动、勿看）'!A10 -> 0 | B10: ='[1]特别隐藏版（勿动、勿看）'!B10 -> 销量目标 | C10: ='[1]2026年度男装汇总分析'!C10 -> 20440 | D10: ='[1]2026年度男装汇总分析'!D10 -> 30070 | E10: ='[1]2026年度男装汇总分析'!E10 -> 33000 | F10: ='[1]2026年度男装汇总分析'!F10 -> 37200 | G10: ='[1]2026年度男装汇总分析'!G10 -> 32100 | H10: ='[1]2026年度男装汇总分析'!H10 -> 33170 | I10: ='[1]2026年度男装汇总分析'!I10 -> 41850 | J10: ='[1]2026年度男装汇总分析'!J10 -> 40500 | ... N10: ='[1]2026年度男装汇总分析'!N10 -> 21700 | O10: =SUM(C10:N10) -> 406580
A11: ='[1]特别隐藏版（勿动、勿看）'!A11 -> 0 | B11: ='[1]特别隐藏版（勿动、勿看）'!B11 -> 销量完成 | C11: ='[1]2026年度男装汇总分析'!C11 -> 20744 | D11: ='[1]2026年度男装汇总分析'!D11 -> 35092 | E11: ='[1]2026年度男装汇总分析'!E11 -> 21224 | F11: ='[1]2026年度男装汇总分析'!F11 -> 27150 | G11: ='[1]2026年度男装汇总分析'!G11 -> 16959 | H11: ='[1]2026年度男装汇总分析'!H11 -> 4091 | I11: ='[1]2026年度男装汇总分析'!I11 -> 0 | J11: ='[1]2026年度男装汇总分析'!J11 -> 0 | ... N11: ='[1]2026年度男装汇总分析'!N11 -> 0 | O11: =SUM(C11:N11) -> 125260
A12: ='[1]特别隐藏版（勿动、勿看）'!A12 -> 0 | B12: ='[1]特别隐藏版（勿动、勿看）'!B12 -> 销量完成进度 | C12: =C11/C10 -> 1.0148728 | D12: =D11/D10 -> 1.1670103 | E12: =E11/E10 -> 0.64315152 | F12: =F11/F10 -> 0.72983871 | G12: =G11/G10 -> 0.52831776 | H12: =H11/H10 -> 0.12333434 | I12: =I11/I10 -> 0 | J12: =J11/J10 -> 0 | ... O12: =O11/O10 -> 0.30808205
A13: ='[1]特别隐藏版（勿动、勿看）'!A13 -> 0 | B13: ='[1]特别隐藏版（勿动、勿看）'!B13 -> 0 | C13: ='[1]特别隐藏版（勿动、勿看）'!C13 -> 0 | D13: ='[1]特别隐藏版（勿动、勿看）'!D13 -> 0 | E13: ='[1]特别隐藏版（勿动、勿看）'!E13 -> 0 | F13: ='[1]特别隐藏版（勿动、勿看）'!F13 -> 0 | G13: ='[1]特别隐藏版（勿动、勿看）'!G13 -> 0 | H13: ='[1]特别隐藏版（勿动、勿看）'!H13 -> 0 | ... O13: ='[1]特别隐藏版（勿动、勿看）'!O13 -> 0
A14: ='[1]特别隐藏版（勿动、勿看）'!A14 -> 0 | B14: ='[1]特别隐藏版（勿动、勿看）'!B14 -> 实销目标 | C14: ='[1]2026年度男装汇总分析'!C14 -> 6897.3576 | D14: ='[1]2026年度男装汇总分析'!D14 -> 10111.687 | E14: ='[1]2026年度男装汇总分析'!E14 -> 11086.227 | F14: ='[1]2026年度男装汇总分析'!F14 -> 12472.055 | G14: ='[1]2026年度男装汇总分析'!G14 -> 10728.765 | H14: ='[1]2026年度男装汇总分析'!H14 -> 11086.39 | I14: ='[1]2026年度男装汇总分析'!I14 -> 13984.806 | J14: ='[1]2026年度男装汇总分析'!J14 -> 13533.683 | ... N14: ='[1]2026年度男装汇总分析'!N14 -> 7213.1483 | O14: ='[1]特别隐藏版（勿动、勿看）'!O14 -> 134432.17
A15: ='[1]特别隐藏版（勿动、勿看）'!A15 -> 0 | B15: ='[1]特别隐藏版（勿动、勿看）'!B15 -> 实销完成 | C15: ='[1]2026年度男装汇总分析'!C15 -> 6365 | D15: ='[1]2026年度男装汇总分析'!D15 -> 9824 | E15: ='[1]2026年度男装汇总分析'!E15 -> 5779 | F15: ='[1]2026年度男装汇总分析'!F15 -> 7790 | G15: ='[1]2026年度男装汇总分析'!G15 -> 5201 | H15: ='[1]2026年度男装汇总分析'!H15 -> 1382 | I15: ='[1]2026年度男装汇总分析'!I15 -> 0 | J15: ='[1]2026年度男装汇总分析'!J15 -> 0 | ... N15: ='[1]2026年度男装汇总分析'!N15 -> 0 | O15: ='[1]特别隐藏版（勿动、勿看）'!O15 -> 45345
A16: ='[1]特别隐藏版（勿动、勿看）'!A16 -> 0 | B16: ='[1]特别隐藏版（勿动、勿看）'!B16 -> 实销完成进度 | C16: =C15/C14 -> 0.92281716 | D16: =D15/D14 -> 0.97154902 | E16: =E15/E14 -> 0.52127745 | F16: =F15/F14 -> 0.62459633 | G16: =G15/G14 -> 0.48477156 | H16: =H15/H14 -> 0.12465735 | I16: =I15/I14 -> 0 | J16: =J15/J14 -> 0 | ... O16: =O15/O14 -> 0.33730766
A17: ='[1]特别隐藏版（勿动、勿看）'!A17 -> 0 | B17: ='[1]特别隐藏版（勿动、勿看）'!B17 -> 0 | C17: ='[1]特别隐藏版（勿动、勿看）'!C17 -> 0 | D17: ='[1]特别隐藏版（勿动、勿看）'!D17 -> 0 | E17: ='[1]特别隐藏版（勿动、勿看）'!E17 -> 0 | F17: ='[1]特别隐藏版（勿动、勿看）'!F17 -> 0 | G17: ='[1]特别隐藏版（勿动、勿看）'!G17 -> 0 | H17: ='[1]特别隐藏版（勿动、勿看）'!H17 -> 0 | ... O17: ='[1]特别隐藏版（勿动、勿看）'!O17 -> 0
A18: ='[1]特别隐藏版（勿动、勿看）'!A18 -> 0 | B18: ='[1]特别隐藏版（勿动、勿看）'!B18 -> GMV目标 | C18: ='[1]2026年度男装汇总分析'!C18 -> 80493092 | D18: ='[1]2026年度男装汇总分析'!D18 -> 1.1908907e+08 | E18: ='[1]2026年度男装汇总分析'!E18 -> 1.3140765e+08 | F18: ='[1]2026年度男装汇总分析'!F18 -> 1.4788553e+08 | G18: ='[1]2026年度男装汇总分析'!G18 -> 1.2792679e+08 | H18: ='[1]2026年度男装汇总分析'!H18 -> 1.3219101e+08 | I18: ='[1]2026年度男装汇总分析'!I18 -> 1.6675712e+08 | J18: ='[1]2026年度男装汇总分析'!J18 -> 1.6137785e+08 | ... N18: ='[1]2026年度男装汇总分析'!N18 -> 86489222 | O18: ='[1]特别隐藏版（勿动、勿看）'!O18 -> 1.7028965e+09
A19: ='[1]特别隐藏版（勿动、勿看）'!A19 -> 0 | B19: ='[1]特别隐藏版（勿动、勿看）'!B19 -> GMV完成 | C19: ='[1]2026年度男装汇总分析'!C19 -> 87962394 | D19: ='[1]2026年度男装汇总分析'!D19 -> 148640998 | E19: ='[1]2026年度男装汇总分析'!E19 -> 95808740 | F19: ='[1]2026年度男装汇总分析'!F19 -> 115730945 | G19: ='[1]2026年度男装汇总分析'!G19 -> 71404757 | H19: ='[1]2026年度男装汇总分析'!H19 -> 20007967 | I19: ='[1]2026年度男装汇总分析'!I19 -> 0 | J19: ='[1]2026年度男装汇总分析'!J19 -> 0 | ... N19: ='[1]2026年度男装汇总分析'!N19 -> 0 | O19: ='[1]特别隐藏版（勿动、勿看）'!O19 -> 739894426
A20: ='[1]特别隐藏版（勿动、勿看）'!A20 -> 0 | B20: ='[1]特别隐藏版（勿动、勿看）'!B20 -> GMV完成进度 | C20: =C19/C18 -> 1.0927943 | D20: =D19/D18 -> 1.2481498 | E20: =E19/E18 -> 0.72909562 | F20: =F19/F18 -> 0.78257111 | G20: =G19/G18 -> 0.55816892 | H20: =H19/H18 -> 0.15135648 | I20: =I19/I18 -> 0 | J20: =J19/J18 -> 0 | ... O20: =O19/O18 -> 0.43449172
A21: ='[1]特别隐藏版（勿动、勿看）'!A21 -> 0 | B21: ='[1]特别隐藏版（勿动、勿看）'!B21 -> 0 | C21: ='[1]特别隐藏版（勿动、勿看）'!C21 -> 0 | D21: ='[1]特别隐藏版（勿动、勿看）'!D21 -> 0 | E21: ='[1]特别隐藏版（勿动、勿看）'!E21 -> 0 | F21: ='[1]特别隐藏版（勿动、勿看）'!F21 -> 0 | G21: ='[1]特别隐藏版（勿动、勿看）'!G21 -> 0 | H21: ='[1]特别隐藏版（勿动、勿看）'!H21 -> 0 | ... O21: ='[1]特别隐藏版（勿动、勿看）'!O21 -> 0
A22: ='[1]特别隐藏版（勿动、勿看）'!A22 -> 0 | B22: ='[1]特别隐藏版（勿动、勿看）'!B22 -> GSV目标 | C22: ='[1]2026年度男装汇总分析'!C22 -> 2071988.3 | D22: ='[1]2026年度男装汇总分析'!D22 -> 3065494.9 | E22: ='[1]2026年度男装汇总分析'!E22 -> 3382589.7 | F22: ='[1]2026年度男装汇总分析'!F22 -> 3806750.1 | G22: ='[1]2026年度男装汇总分析'!G22 -> 3292988.2 | H22: ='[1]2026年度男装汇总分析'!H22 -> 3402754.5 | I22: ='[1]2026年度男装汇总分析'!I22 -> 4292527.2 | J22: ='[1]2026年度男装汇总分析'!J22 -> 4154058.6 | ... N22: ='[1]2026年度男装汇总分析'!N22 -> 2226335.8 | O22: ='[1]特别隐藏版（勿动、勿看）'!O22 -> 43834589
A23: ='[1]特别隐藏版（勿动、勿看）'!A23 -> 0 | B23: ='[1]特别隐藏版（勿动、勿看）'!B23 -> GSV完成 | C23: ='[1]2026年度男装汇总分析'!C23 -> 2304945 | D23: ='[1]2026年度男装汇总分析'!D23 -> 3779574.7 | E23: ='[1]2026年度男装汇总分析'!E23 -> 2243082.8 | F23: ='[1]2026年度男装汇总分析'!F23 -> 3000516.4 | G23: ='[1]2026年度男装汇总分析'!G23 -> 2098469.2 | H23: ='[1]2026年度男装汇总分析'!H23 -> 519949.84 | I23: ='[1]2026年度男装汇总分析'!I23 -> 0 | J23: ='[1]2026年度男装汇总分析'!J23 -> 0 | ... N23: ='[1]2026年度男装汇总分析'!N23 -> 0 | O23: ='[1]特别隐藏版（勿动、勿看）'!O23 -> 17853620
A24: ='[1]特别隐藏版（勿动、勿看）'!A24 -> 0 | B24: ='[1]特别隐藏版（勿动、勿看）'!B24 -> GSV完成进度 | C24: =C23/C22 -> 1.1124315 | D24: =D23/D22 -> 1.2329411 | E24: =E23/E22 -> 0.66312588 | F24: =F23/F22 -> 0.78820945 | G24: =G23/G22 -> 0.63725379 | H24: =H23/H22 -> 0.15280263 | I24: =I23/I22 -> 0 | J24: =J23/J22 -> 0 | ... O24: =O23/O22 -> 0.40729525
A25: ='[1]特别隐藏版（勿动、勿看）'!A25 -> 0 | B25: ='[1]特别隐藏版（勿动、勿看）'!B25 -> 0 | C25: ='[1]特别隐藏版（勿动、勿看）'!C25 -> 0 | D25: ='[1]特别隐藏版（勿动、勿看）'!D25 -> 0 | E25: ='[1]特别隐藏版（勿动、勿看）'!E25 -> 0 | F25: ='[1]特别隐藏版（勿动、勿看）'!F25 -> 0 | G25: ='[1]特别隐藏版（勿动、勿看）'!G25 -> 0 | H25: ='[1]特别隐藏版（勿动、勿看）'!H25 -> 0 | ... O25: ='[1]特别隐藏版（勿动、勿看）'!O25 -> 0
A26: ='[1]特别隐藏版（勿动、勿看）'!A26 -> 0 | B26: ='[1]特别隐藏版（勿动、勿看）'!B26 -> 退款率 | C26: ='[1]特别隐藏版（勿动、勿看）'!C26 -> 0.68771324 | D26: ='[1]特别隐藏版（勿动、勿看）'!D26 -> 0.69860473 | E26: ='[1]特别隐藏版（勿动、勿看）'!E26 -> 0.72901266 | F26: ='[1]特别隐藏版（勿动、勿看）'!F26 -> 0.70390916 | G26: ='[1]特别隐藏版（勿动、勿看）'!G26 -> 0.66585209 | H26: ='[1]特别隐藏版（勿动、勿看）'!H26 -> 0.69022457 | ... O26: ='[1]特别隐藏版（勿动、勿看）'!O26 -> 0.69837555
A27: ='[1]特别隐藏版（勿动、勿看）'!A27 -> 0 | B27: ='[1]特别隐藏版（勿动、勿看）'!B27 -> 退货率 | C27: ='[1]特别隐藏版（勿动、勿看）'!C27 -> 0.69923831 | D27: ='[1]特别隐藏版（勿动、勿看）'!D27 -> 0.72919805 | E27: ='[1]特别隐藏版（勿动、勿看）'!E27 -> 0.7443399 | F27: ='[1]特别隐藏版（勿动、勿看）'!F27 -> 0.73319251 | G27: ='[1]特别隐藏版（勿动、勿看）'!G27 -> 0.7208584 | H27: ='[1]特别隐藏版（勿动、勿看）'!H27 -> 0.66335175 | ... O27: ='[1]特别隐藏版（勿动、勿看）'!O27 -> 0.72487668
A28: ='[1]特别隐藏版（勿动、勿看）'!A28 -> 0 | B28: ='[1]特别隐藏版（勿动、勿看）'!B28 -> 利润率 | C28: ='[1]特别隐藏版（勿动、勿看）'!C28 -> 0.13891014 | D28: ='[1]特别隐藏版（勿动、勿看）'!D28 -> 0.13986778 | E28: ='[1]特别隐藏版（勿动、勿看）'!E28 -> 0.062826796 | F28: ='[1]特别隐藏版（勿动、勿看）'!F28 -> 0.10809504 | G28: ='[1]特别隐藏版（勿动、勿看）'!G28 -> 0.11325928 | H28: ='[1]特别隐藏版（勿动、勿看）'!H28 -> 0.13193502 | ... O28: ='[1]特别隐藏版（勿动、勿看）'!O28 -> 0.11599397
A29: ='[1]特别隐藏版（勿动、勿看）'!A29 -> 0 | B29: ='[1]特别隐藏版（勿动、勿看）'!B29 -> 0 | C29: ='[1]特别隐藏版（勿动、勿看）'!C29 -> 0 | D29: ='[1]特别隐藏版（勿动、勿看）'!D29 -> 0 | E29: ='[1]特别隐藏版（勿动、勿看）'!E29 -> 0 | F29: ='[1]特别隐藏版（勿动、勿看）'!F29 -> 0 | G29: ='[1]特别隐藏版（勿动、勿看）'!G29 -> 0 | H29: ='[1]特别隐藏版（勿动、勿看）'!H29 -> 0 | ... O29: ='[1]特别隐藏版（勿动、勿看）'!O29 -> 0
A30: ='[1]特别隐藏版（勿动、勿看）'!A30 -> LXTF1店 | B30: ='[1]特别隐藏版（勿动、勿看）'!B30 -> 实际利润（人民币） | C30: ='[1]2026年度男装汇总分析'!C30 -> 95377.04 | D30: ='[1]2026年度男装汇总分析'!D30 -> 119066.85 | E30: ='[1]2026年度男装汇总分析'!E30 -> 30031.35 | F30: ='[1]2026年度男装汇总分析'!F30 -> 51410.92 | G30: ='[1]2026年度男装汇总分析'!G30 -> 60265.923 | H30: ='[1]2026年度男装汇总分析'!H30 -> 31393.698 | I30: ='[1]2026年度男装汇总分析'!I30 -> 0 | J30: ='[1]2026年度男装汇总分析'!J30 -> 0 | ... N30: ='[1]2026年度男装汇总分析'!N30 -> 0 | O30: =SUM(C30:N30) -> 387545.78
A31: ='[1]特别隐藏版（勿动、勿看）'!A31 -> 0 | B31: ='[1]特别隐藏版（勿动、勿看）'!B31 -> 销量完成 | C31: ='[1]2026年度男装汇总分析'!C31 -> 7692 | D31: ='[1]2026年度男装汇总分析'!D31 -> 11912 | E31: ='[1]2026年度男装汇总分析'!E31 -> 7904 | F31: ='[1]2026年度男装汇总分析'!F31 -> 8430 | G31: ='[1]2026年度男装汇总分析'!G31 -> 5569 | H31: ='[1]2026年度男装汇总分析'!H31 -> 1636 | I31: ='[1]2026年度男装汇总分析'!I31 -> 0 | J31: ='[1]2026年度男装汇总分析'!J31 -> 0 | ... N31: ='[1]2026年度男装汇总分析'!N31 -> 0 | O31: =SUM(C31:N31) -> 43143
A32: ='[1]特别隐藏版（勿动、勿看）'!A32 -> 0 | B32: ='[1]特别隐藏版（勿动、勿看）'!B32 -> 实销完成 | C32: ='[1]2026年度男装汇总分析'!C32 -> 2167 | D32: ='[1]2026年度男装汇总分析'!D32 -> 3045 | E32: ='[1]2026年度男装汇总分析'!E32 -> 1899 | F32: ='[1]2026年度男装汇总分析'!F32 -> 2131 | G32: ='[1]2026年度男装汇总分析'!G32 -> 1563 | H32: ='[1]2026年度男装汇总分析'!H32 -> 494 | I32: ='[1]2026年度男装汇总分析'!I32 -> 0 | J32: ='[1]2026年度男装汇总分析'!J32 -> 0 | ... N32: ='[1]2026年度男装汇总分析'!N32 -> 0 | O32: =SUM(C32:N32) -> 11299
A33: ='[1]特别隐藏版（勿动、勿看）'!A33 -> 0 | B33: ='[1]特别隐藏版（勿动、勿看）'!B33 -> GMV完成 | C33: ='[1]2026年度男装汇总分析'!C33 -> 31682878 | D33: ='[1]2026年度男装汇总分析'!D33 -> 51404385 | E33: ='[1]2026年度男装汇总分析'!E33 -> 35413028 | F33: ='[1]2026年度男装汇总分析'!F33 -> 35782129 | G33: ='[1]2026年度男装汇总分析'!G33 -> 24581134 | H33: ='[1]2026年度男装汇总分析'!H33 -> 7574176 | I33: ='[1]2026年度男装汇总分析'!I33 -> 0 | J33: ='[1]2026年度男装汇总分析'!J33 -> 0 | ... N33: ='[1]2026年度男装汇总分析'!N33 -> 0 | O33: =SUM(C33:N33) -> 186437730
A34: ='[1]特别隐藏版（勿动、勿看）'!A34 -> 0 | B34: ='[1]特别隐藏版（勿动、勿看）'!B34 -> GSV完成 | C34: ='[1]2026年度男装汇总分析'!C34 -> 784712.64 | D34: ='[1]2026年度男装汇总分析'!D34 -> 1179892.5 | E34: ='[1]2026年度男装汇总分析'!E34 -> 724171.24 | F34: ='[1]2026年度男装汇总分析'!F34 -> 833536.12 | G34: ='[1]2026年度男装汇总分析'!G34 -> 635264.53 | H34: ='[1]2026年度男装汇总分析'!H34 -> 185644.94 | I34: ='[1]2026年度男装汇总分析'!I34 -> 0 | J34: ='[1]2026年度男装汇总分析'!J34 -> 0 | ... N34: ='[1]2026年度男装汇总分析'!N34 -> 0 | O34: =SUM(C34:N34) -> 4343222
A35: ='[1]特别隐藏版（勿动、勿看）'!A35 -> 0 | B35: ='[1]特别隐藏版（勿动、勿看）'!B35 -> 退款率 | C35: =1-C34*12.5/C33 -> 0.6904035 | D35: =1-D34*12.5/D33 -> 0.71308564 | E35: =1-E34*12.5/E33 -> 0.74438389 | F35: =1-F34*12.5/F33 -> 0.7088155 | G35: =1-G34*12.5/G33 -> 0.67695524 | H35: =1-H34*12.5/H33 -> 0.69362189 | I35: =1-I34*12.5/I33 -> #DIV/0! | J35: =1-J34*12.5/J33 -> #DIV/0! | ... O35: =1-O34*12.5/O33 -> 0.70880211
A36: ='[1]特别隐藏版（勿动、勿看）'!A36 -> 0 | B36: ='[1]特别隐藏版（勿动、勿看）'!B36 -> 退货率 | C36: =1-C32/C31 -> 0.71827873 | D36: =1-D32/D31 -> 0.74437542 | E36: =1-E32/E31 -> 0.7597419 | F36: =1-F32/F31 -> 0.74721234 | G36: =1-G32/G31 -> 0.7193392 | H36: =1-H32/H31 -> 0.69804401 | I36: =1-I32/I31 -> #DIV/0! | J36: =1-J32/J31 -> #DIV/0! | ... O36: =1-O32/O31 -> 0.73810352
A37: ='[1]特别隐藏版（勿动、勿看）'!A37 -> 0 | B37: ='[1]特别隐藏版（勿动、勿看）'!B37 -> 利润率 | C37: =C30/(C34) -> 0.12154391 | D37: =D30/(D34) -> 0.1009133 | E37: =E30/(E34) -> 0.041469957 | F37: =F30/(F34) -> 0.061678095 | G37: =G30/(G34) -> 0.094867446 | H37: =H30/(H34) -> 0.16910613 | I37: =I30/(I34) -> #DIV/0! | J37: =J30/(J34) -> #DIV/0! | ... O37: =O30/(O34) -> 0.08923002
A38: ='[1]特别隐藏版（勿动、勿看）'!A38 -> LXTF2店 | B38: ='[1]特别隐藏版（勿动、勿看）'!B38 -> 实际利润（人民币） | C38: ='[1]2026年度男装汇总分析'!C38 -> 87149.73 | D38: ='[1]2026年度男装汇总分析'!D38 -> 219445.1 | E38: ='[1]2026年度男装汇总分析'!E38 -> 53171.99 | F38: ='[1]2026年度男装汇总分析'!F38 -> 99083.11 | G38: ='[1]2026年度男装汇总分析'!G38 -> 105724.5 | H38: ='[1]2026年度男装汇总分析'!H38 -> 24878.611 | I38: ='[1]2026年度男装汇总分析'!I38 -> 0 | J38: ='[1]2026年度男装汇总分析'!J38 -> 0 | ... N38: ='[1]2026年度男装汇总分析'!N38 -> 0 | O38: =SUM(C38:N38) -> 589453.04
A39: ='[1]特别隐藏版（勿动、勿看）'!A39 -> 0 | B39: ='[1]特别隐藏版（勿动、勿看）'!B39 -> 销量完成 | C39: ='[1]2026年度男装汇总分析'!C39 -> 6846 | D39: ='[1]2026年度男装汇总分析'!D39 -> 12313 | E39: ='[1]2026年度男装汇总分析'!E39 -> 6346 | F39: ='[1]2026年度男装汇总分析'!F39 -> 8877 | G39: ='[1]2026年度男装汇总分析'!G39 -> 5984 | H39: ='[1]2026年度男装汇总分析'!H39 -> 1370 | I39: ='[1]2026年度男装汇总分析'!I39 -> 0 | J39: ='[1]2026年度男装汇总分析'!J39 -> 0 | ... N39: ='[1]2026年度男装汇总分析'!N39 -> 0 | O39: =SUM(C39:N39) -> 41736
A40: ='[1]特别隐藏版（勿动、勿看）'!A40 -> 0 | B40: ='[1]特别隐藏版（勿动、勿看）'!B40 -> 实销完成 | C40: ='[1]2026年度男装汇总分析'!C40 -> 2045 | D40: ='[1]2026年度男装汇总分析'!D40 -> 3425 | E40: ='[1]2026年度男装汇总分析'!E40 -> 1778 | F40: ='[1]2026年度男装汇总分析'!F40 -> 2609 | G40: ='[1]2026年度男装汇总分析'!G40 -> 1837 | H40: ='[1]2026年度男装汇总分析'!H40 -> 418 | I40: ='[1]2026年度男装汇总分析'!I40 -> 0 | J40: ='[1]2026年度男装汇总分析'!J40 -> 0 | ... N40: ='[1]2026年度男装汇总分析'!N40 -> 0 | O40: =SUM(C40:N40) -> 12112
...

Sheet 张梦瑶
A1: ='[2]2026年度男装数据汇总分析--俄罗斯'!A1 -> 2026年度WB男装进度 | B1: ='[2]2026年度男装数据汇总分析--俄罗斯'!B1 -> 0 | C1: ='[2]2026年度男装数据汇总分析--俄罗斯'!C1 -> 0 | D1: ='[2]2026年度男装数据汇总分析--俄罗斯'!D1 -> 0 | E1: ='[2]2026年度男装数据汇总分析--俄罗斯'!E1 -> 0 | F1: ='[2]2026年度男装数据汇总分析--俄罗斯'!F1 -> 0 | G1: ='[2]2026年度男装数据汇总分析--俄罗斯'!G1 -> 0 | H1: ='[2]2026年度男装数据汇总分析--俄罗斯'!H1 -> 0 | ... O1: ='[2]2026年度男装数据汇总分析--俄罗斯'!O1 -> 0
A2: ='[2]2026年度男装数据汇总分析--俄罗斯'!A2 -> 项目 | B2: ='[2]2026年度男装数据汇总分析--俄罗斯'!B2 -> 月度 | C2: ='[2]2026年度男装数据汇总分析--俄罗斯'!C2 -> 2月 | D2: ='[2]2026年度男装数据汇总分析--俄罗斯'!D2 -> 3月 | E2: ='[2]2026年度男装数据汇总分析--俄罗斯'!E2 -> 4月 | F2: ='[2]2026年度男装数据汇总分析--俄罗斯'!F2 -> 5月 | G2: ='[2]2026年度男装数据汇总分析--俄罗斯'!G2 -> 6月 | H2: ='[2]2026年度男装数据汇总分析--俄罗斯'!H2 -> 7月 | ... O2: ='[2]2026年度男装数据汇总分析--俄罗斯'!O2 -> 汇总
A3: ='[2]2026年度男装数据汇总分析--俄罗斯'!A3 -> 0 | B3: ='[2]2026年度男装数据汇总分析--俄罗斯'!B3 -> 季度 | C3: ='[2]2026年度男装数据汇总分析--俄罗斯'!C3 -> Q1 | D3: ='[2]2026年度男装数据汇总分析--俄罗斯'!D3 -> 0 | E3: ='[2]2026年度男装数据汇总分析--俄罗斯'!E3 -> 0 | F3: ='[2]2026年度男装数据汇总分析--俄罗斯'!F3 -> Q2 | G3: ='[2]2026年度男装数据汇总分析--俄罗斯'!G3 -> 0 | H3: ='[2]2026年度男装数据汇总分析--俄罗斯'!H3 -> 0 | ... O3: ='[2]2026年度男装数据汇总分析--俄罗斯'!O3 -> 0
A4: ='[2]2026年度男装数据汇总分析--俄罗斯'!A4 -> 0 | B4: ='[2]2026年度男装数据汇总分析--俄罗斯'!B4 -> 季度财报 | C4: =(C7+D7+E7) -> 1812058.5 | F4: =(F7+G7+H7) -> 1460931.3 | I4: =(I7+J7+K7) -> 0 | L4: =(L7+M7+N7) -> 0 | O4: ='[2]2026年度男装数据汇总分析--俄罗斯'!O4 -> 0
A5: ='[2]2026年度男装数据汇总分析--俄罗斯'!A5 -> 0 | B5: ='[2]2026年度男装数据汇总分析--俄罗斯'!B5 -> 季度财报进度 | C5: =(C7+D7+E7)/(C6+D6+E6) -> 1.311832 | F5: =(F7+G7+H7)/(F6+G6+H6) -> 0.90521395 | I5: =(I7+J7+K7)/(I6+J6+K6) -> 0 | L5: =(L7+M7+N7)/(L6+M6+N6) -> 0 | O5: ='[2]2026年度男装数据汇总分析--俄罗斯'!O5 -> 0
A6: ='[2]2026年度男装数据汇总分析--俄罗斯'!A6 -> 目标完成情况 | B6: ='[2]2026年度男装数据汇总分析--俄罗斯'!B6 -> 月度目标 利润（人民币） | C6: ='[2]2026年度男装数据汇总分析--俄罗斯'!C6 -> 445623.09 | D6: ='[2]2026年度男装数据汇总分析--俄罗斯'!D6 -> 485784.48 | E6: ='[2]2026年度男装数据汇总分析--俄罗斯'!E6 -> 449911.44 | F6: ='[2]2026年度男装数据汇总分析--俄罗斯'!F6 -> 464012.75 | G6: ='[2]2026年度男装数据汇总分析--俄罗斯'!G6 -> 543194.4 | H6: ='[2]2026年度男装数据汇总分析--俄罗斯'!H6 -> 606700.06 | ... O6: ='[2]2026年度男装数据汇总分析--俄罗斯'!O6 -> 8755270.4
A7: ='[2]2026年度男装数据汇总分析--俄罗斯'!A7 -> 0 | B7: ='[2]2026年度男装数据汇总分析--俄罗斯'!B7 -> 实际利润（人民币） | C7: ='[2]2026年度男装数据汇总分析--俄罗斯'!C7 -> 573037.44 | D7: ='[2]2026年度男装数据汇总分析--俄罗斯'!D7 -> 647037.05 | E7: ='[2]2026年度男装数据汇总分析--俄罗斯'!E7 -> 591983.98 | F7: ='[2]2026年度男装数据汇总分析--俄罗斯'!F7 -> 706739.4 | G7: ='[2]2026年度男装数据汇总分析--俄罗斯'!G7 -> 593421.46 | H7: ='[2]2026年度男装数据汇总分析--俄罗斯'!H7 -> 160770.45 | ... O7: ='[2]2026年度男装数据汇总分析--俄罗斯'!O7 -> 3272989.8
A8: ='[2]2026年度男装数据汇总分析--俄罗斯'!A8 -> 0 | B8: ='[2]2026年度男装数据汇总分析--俄罗斯'!B8 -> 目标完成进度 | C8: ='[2]2026年度男装数据汇总分析--俄罗斯'!C8 -> 1.285924 | D8: ='[2]2026年度男装数据汇总分析--俄罗斯'!D8 -> 1.3319426 | E8: ='[2]2026年度男装数据汇总分析--俄罗斯'!E8 -> 1.3157789 | F8: ='[2]2026年度男装数据汇总分析--俄罗斯'!F8 -> 1.5231034 | G8: ='[2]2026年度男装数据汇总分析--俄罗斯'!G8 -> 1.0924661 | H8: ='[2]2026年度男装数据汇总分析--俄罗斯'!H8 -> 0.26499165 | ... O8: ='[2]2026年度男装数据汇总分析--俄罗斯'!O8 -> 0.3738308
A9: ='[2]2026年度男装数据汇总分析--俄罗斯'!A9 -> 0 | B9: ='[2]2026年度男装数据汇总分析--俄罗斯'!B9 -> 0 | C9: ='[2]2026年度男装数据汇总分析--俄罗斯'!C9 -> 0 | D9: ='[2]2026年度男装数据汇总分析--俄罗斯'!D9 -> 0 | E9: ='[2]2026年度男装数据汇总分析--俄罗斯'!E9 -> 0 | F9: ='[2]2026年度男装数据汇总分析--俄罗斯'!F9 -> 0 | G9: ='[2]2026年度男装数据汇总分析--俄罗斯'!G9 -> 0 | H9: ='[2]2026年度男装数据汇总分析--俄罗斯'!H9 -> 0 | ... O9: ='[2]2026年度男装数据汇总分析--俄罗斯'!O9 -> 0
A10: ='[2]2026年度男装数据汇总分析--俄罗斯'!A10 -> 0 | B10: ='[2]2026年度男装数据汇总分析--俄罗斯'!B10 -> 销量目标 | C10: ='[2]2026年度男装数据汇总分析--俄罗斯'!C10 -> 29092 | D10: ='[2]2026年度男装数据汇总分析--俄罗斯'!D10 -> 31620 | E10: ='[2]2026年度男装数据汇总分析--俄罗斯'!E10 -> 29700 | F10: ='[2]2026年度男装数据汇总分析--俄罗斯'!F10 -> 31930 | G10: ='[2]2026年度男装数据汇总分析--俄罗斯'!G10 -> 36000 | H10: ='[2]2026年度男装数据汇总分析--俄罗斯'!H10 -> 40207 | ... O10: ='[2]2026年度男装数据汇总分析--俄罗斯'!O10 -> 580872
A11: ='[2]2026年度男装数据汇总分析--俄罗斯'!A11 -> 0 | B11: ='[2]2026年度男装数据汇总分析--俄罗斯'!B11 -> 销量完成 | C11: ='[2]2026年度男装数据汇总分析--俄罗斯'!C11 -> 29860 | D11: ='[2]2026年度男装数据汇总分析--俄罗斯'!D11 -> 32519 | E11: ='[2]2026年度男装数据汇总分析--俄罗斯'!E11 -> 32812 | F11: ='[2]2026年度男装数据汇总分析--俄罗斯'!F11 -> 33812 | G11: ='[2]2026年度男装数据汇总分析--俄罗斯'!G11 -> 26753 | H11: ='[2]2026年度男装数据汇总分析--俄罗斯'!H11 -> 7111 | ... O11: ='[2]2026年度男装数据汇总分析--俄罗斯'!O11 -> 162867
A12: ='[2]2026年度男装数据汇总分析--俄罗斯'!A12 -> 0 | B12: ='[2]2026年度男装数据汇总分析--俄罗斯'!B12 -> 销量完成进度 | C12: ='[2]2026年度男装数据汇总分析--俄罗斯'!C12 -> 1.026399 | D12: ='[2]2026年度男装数据汇总分析--俄罗斯'!D12 -> 1.0284314 | E12: ='[2]2026年度男装数据汇总分析--俄罗斯'!E12 -> 1.1047811 | F12: ='[2]2026年度男装数据汇总分析--俄罗斯'!F12 -> 1.0589414 | G12: ='[2]2026年度男装数据汇总分析--俄罗斯'!G12 -> 0.74313889 | H12: ='[2]2026年度男装数据汇总分析--俄罗斯'!H12 -> 0.17685975 | ... O12: ='[2]2026年度男装数据汇总分析--俄罗斯'!O12 -> 0.28038363
A13: ='[2]2026年度男装数据汇总分析--俄罗斯'!A13 -> 0 | B13: ='[2]2026年度男装数据汇总分析--俄罗斯'!B13 -> 0 | C13: ='[2]2026年度男装数据汇总分析--俄罗斯'!C13 -> 0 | D13: ='[2]2026年度男装数据汇总分析--俄罗斯'!D13 -> 0 | E13: ='[2]2026年度男装数据汇总分析--俄罗斯'!E13 -> 0 | F13: ='[2]2026年度男装数据汇总分析--俄罗斯'!F13 -> 0 | G13: ='[2]2026年度男装数据汇总分析--俄罗斯'!G13 -> 0 | H13: ='[2]2026年度男装数据汇总分析--俄罗斯'!H13 -> 0 | ... O13: ='[2]2026年度男装数据汇总分析--俄罗斯'!O13 -> 0
A14: ='[2]2026年度男装数据汇总分析--俄罗斯'!A14 -> 0 | B14: ='[2]2026年度男装数据汇总分析--俄罗斯'!B14 -> 实销目标 | C14: ='[2]2026年度男装数据汇总分析--俄罗斯'!C14 -> 9018.52 | D14: ='[2]2026年度男装数据汇总分析--俄罗斯'!D14 -> 9802.2 | E14: ='[2]2026年度男装数据汇总分析--俄罗斯'!E14 -> 9207 | F14: ='[2]2026年度男装数据汇总分析--俄罗斯'!F14 -> 9898.3 | G14: ='[2]2026年度男装数据汇总分析--俄罗斯'!G14 -> 11160 | H14: ='[2]2026年度男装数据汇总分析--俄罗斯'!H14 -> 12464.17 | ... O14: ='[2]2026年度男装数据汇总分析--俄罗斯'!O14 -> 180070.32
A15: ='[2]2026年度男装数据汇总分析--俄罗斯'!A15 -> 0 | B15: ='[2]2026年度男装数据汇总分析--俄罗斯'!B15 -> 实销完成 | C15: ='[2]2026年度男装数据汇总分析--俄罗斯'!C15 -> 10171 | D15: ='[2]2026年度男装数据汇总分析--俄罗斯'!D15 -> 11583 | E15: ='[2]2026年度男装数据汇总分析--俄罗斯'!E15 -> 12133 | F15: ='[2]2026年度男装数据汇总分析--俄罗斯'!F15 -> 12177 | G15: ='[2]2026年度男装数据汇总分析--俄罗斯'!G15 -> 9282 | H15: ='[2]2026年度男装数据汇总分析--俄罗斯'!H15 -> 2512 | ... O15: ='[2]2026年度男装数据汇总分析--俄罗斯'!O15 -> 57858
A16: ='[2]2026年度男装数据汇总分析--俄罗斯'!A16 -> 0 | B16: ='[2]2026年度男装数据汇总分析--俄罗斯'!B16 -> 实销完成进度 | C16: ='[2]2026年度男装数据汇总分析--俄罗斯'!C16 -> 1.1277904 | D16: ='[2]2026年度男装数据汇总分析--俄罗斯'!D16 -> 1.1816735 | E16: ='[2]2026年度男装数据汇总分析--俄罗斯'!E16 -> 1.3178017 | F16: ='[2]2026年度男装数据汇总分析--俄罗斯'!F16 -> 1.2302112 | G16: ='[2]2026年度男装数据汇总分析--俄罗斯'!G16 -> 0.83172043 | H16: ='[2]2026年度男装数据汇总分析--俄罗斯'!H16 -> 0.20153769 | ... O16: ='[2]2026年度男装数据汇总分析--俄罗斯'!O16 -> 0.32130781
A17: ='[2]2026年度男装数据汇总分析--俄罗斯'!A17 -> 0 | B17: ='[2]2026年度男装数据汇总分析--俄罗斯'!B17 -> 0 | C17: ='[2]2026年度男装数据汇总分析--俄罗斯'!C17 -> 0 | D17: ='[2]2026年度男装数据汇总分析--俄罗斯'!D17 -> 0 | E17: ='[2]2026年度男装数据汇总分析--俄罗斯'!E17 -> 0 | F17: ='[2]2026年度男装数据汇总分析--俄罗斯'!F17 -> 0 | G17: ='[2]2026年度男装数据汇总分析--俄罗斯'!G17 -> 0 | H17: ='[2]2026年度男装数据汇总分析--俄罗斯'!H17 -> 0 | ... O17: ='[2]2026年度男装数据汇总分析--俄罗斯'!O17 -> 0
... A162: ='[2]2026年度男装数据汇总分析--俄罗斯'!A162 -> 0 | B162: ='[2]2026年度男装数据汇总分析--俄罗斯'!B162 -> 0 | C162: ='[2]2026年度男装数据汇总分析--俄罗斯'!C162 -> 0 | D162: ='[2]2026年度男装数据汇总分析--俄罗斯'!D162 -> 0 | E162: ='[2]2026年度男装数据汇总分析--俄罗斯'!E162 -> 0 | F162: ='[2]2026年度男装数据汇总分析--俄罗斯'!F162 -> 0 | G162: ='[2]2026年度男装数据汇总分析--俄罗斯'!G162 -> 0 | H162: ='[2]2026年度男装数据汇总分析--俄罗斯'!H162 -> 0 | ... O162: ='[2]2026年度男装数据汇总分析--俄罗斯'!O162 -> 0

Sheet 江凯伦
A1: 2026年度WB进度
A2: 项目 | B2: 月度 | C2: 2月 | D2: 3月 | E2: 4月 | F2: 5月 | G2: 6月 | H2: 7月 | I2: 8月 | J2: 9月 | K2: 10月 | L2: 11月 | M2: 12月 | N2: 1月 | O2: 汇总
B3: 季度 | C3: Q1 | F3: Q2 | I3: Q3 | L3: Q4
B4: 季度财报 | C4: =(C7+D7+E7) -> 1841615.4 | F4: =(F7+G7+H7) -> 1069636.2 | I4: =(I7+J7+K7) -> 0 | L4: =(L7+M7+N7) -> 0
B5: 季度财报进度 | C5: =(C7+D7+E7)/(C6+D6+E6) -> 0.81579754 | F5: =(F7+G7+H7)/(F6+G6+H6) -> 0.53287015 | I5: =(I7+J7+K7)/(I6+J6+K6) -> 0 | L5: =(L7+M7+N7)/(L6+M6+N6) -> 0
A6: 目标完成情况 | B6: 月度目标 利润（人民币） | C6: =[3]总目标!B18 -> 622242.55 | D6: =[3]总目标!C18 -> 926202.86 | E6: =[3]总目标!D18 -> 708996.27 | F6: =[3]总目标!E18 -> 720242.5 | G6: =[3]总目标!F18 -> 690073.45 | H6: =[3]总目标!G18 -> 596995.2 | I6: =[3]总目标!H18 -> 773183.93 | J6: =[3]总目标!I18 -> 743318.08 | ... N6: =[3]总目标!M18 -> 471239.13 | O6: =SUM(C6:N6) -> 8392422.3
B7: 实际利润（人民币） | C7: =[3]总目标!B19+[3]总目标!B20+[3]总目标!B21+[3]总目标!B22+[3]总目标!B23 -> 0 | D7: =[3]总目标!C19+[3]总目标!C20+[3]总目标!C21+[3]总目标!C22+[3]总目标!C23 -> 1166041.2 | E7: =[3]总目标!D19+[3]总目标!D20+[3]总目标!D21+[3]总目标!D22+[3]总目标!D23 -> 675574.18 | F7: =[3]总目标!E19+[3]总目标!E20+[3]总目标!E21+[3]总目标!E22+[3]总目标!E23 -> 916564.03 | G7: =[3]总目标!F19+[3]总目标!F20+[3]总目标!F21+[3]总目标!F22+[3]总目标!F23 -> 153072.16 | H7: =[3]总目标!G19+[3]总目标!G20+[3]总目标!G21+[3]总目标!G22+[3]总目标!G23 -> 0 | I7: =[3]总目标!H19+[3]总目标!H20+[3]总目标!H21+[3]总目标!H22+[3]总目标!H23 -> 0 | J7: =[3]总目标!I19+[3]总目标!I20+[3]总目标!I21+[3]总目标!I22+[3]总目标!I23 -> 0 | ... N7: =[3]总目标!M19+[3]总目标!M20+[3]总目标!M21+[3]总目标!M22+[3]总目标!M23 -> 0 | O7: =SUM(C7:N7) -> 2911251.6
B8: 目标完成进度 | C8: =C7/C6 -> 0 | D8: =D7/D6 -> 1.258948 | E8: =E7/E6 -> 0.95285999 | F8: =F7/F6 -> 1.272577 | G8: =G7/G6 -> 0.2218201 | H8: =H7/H6 -> 0 | I8: =I7/I6 -> 0 | J8: =J7/J6 -> 0 | ... O8: =O7/O6 -> 0.3468905
B10: 销量目标
B11: 销量完成
B12: 销量完成进度
B14: 实销目标
B15: 实销完成
B16: 实销完成进度
B18: GMV目标
B19: GMV完成
B20: GMV完成进度
B22: GSV目标
B23: GSV完成
B24: GSV完成进度
... B28: 利润率

Sheet 陈欣诺
A1: 2026年度WB进度
A2: 项目 | B2: 月度 | C2: 2月 | D2: 3月 | E2: 4月 | F2: 5月 | G2: 6月 | H2: 7月 | I2: 8月 | J2: 9月 | K2: 10月 | L2: 11月 | M2: 12月 | N2: 1月 | O2: 汇总
B3: 季度 | C3: Q1 | F3: Q2 | I3: Q3 | L3: Q4
B4: 季度财报 | C4: =(C7+D7+E7) -> 0 | F4: =(F7+G7+H7) -> 311221.61 | I4: =(I7+J7+K7) -> 0 | L4: =(L7+M7+N7) -> 0
B5: 季度财报进度 | C5: =(C7+D7+E7)/(C6+D6+E6) -> 0 | F5: =(F7+G7+H7)/(F6+G6+H6) -> 0.35055624 | I5: =(I7+J7+K7)/(I6+J6+K6) -> 0 | L5: =(L7+M7+N7)/(L6+M6+N6) -> 0
A6: 目标完成情况 | B6: 月度目标 利润（人民币） | C6: =[3]总目标!B31 -> 249399.55 | D6: =[3]总目标!C31 -> 359988.36 | E6: =[3]总目标!D31 -> 283015.08 | F6: =[3]总目标!E31 -> 292149.34 | G6: =[3]总目标!F31 -> 251744.8 | H6: =[3]总目标!G31 -> 343899.52 | I6: =[3]总目标!H31 -> 432694.44 | J6: =[3]总目标!I31 -> 416424.59 | ... N6: =[3]总目标!M31 -> 262747.87 | O6: =SUM(C6:N6) -> 4072743.3
B7: 实际利润（人民币） | C7: =[3]总目标!B32+[3]总目标!B33+[3]总目标!B34+[3]总目标!B35+[3]总目标!B36 -> 0 | D7: =[3]总目标!C32+[3]总目标!C33+[3]总目标!C34+[3]总目标!C35+[3]总目标!C36 -> 0 | E7: =[3]总目标!D32+[3]总目标!D33+[3]总目标!D34+[3]总目标!D35+[3]总目标!D36 -> 0 | F7: =[3]总目标!E32+[3]总目标!E33+[3]总目标!E34+[3]总目标!E35+[3]总目标!E36 -> 0 | G7: =[3]总目标!F32+[3]总目标!F33+[3]总目标!F34+[3]总目标!F35+[3]总目标!F36 -> 311221.61 | H7: =[3]总目标!G32+[3]总目标!G33+[3]总目标!G34+[3]总目标!G35+[3]总目标!G36 -> 0 | I7: =[3]总目标!H32+[3]总目标!H33+[3]总目标!H34+[3]总目标!H35+[3]总目标!H36 -> 0 | J7: =[3]总目标!I32+[3]总目标!I33+[3]总目标!I34+[3]总目标!I35+[3]总目标!I36 -> 0 | ... N7: =[3]总目标!M32+[3]总目标!M33+[3]总目标!M34+[3]总目标!M35+[3]总目标!M36 -> 0 | O7: =SUM(C7:N7) -> 311221.61
B8: 目标完成进度 | C8: =C7/C6 -> 0 | D8: =D7/D6 -> 0 | E8: =E7/E6 -> 0 | F8: =F7/F6 -> 0 | G8: =G7/G6 -> 1.2362583 | H8: =H7/H6 -> 0 | I8: =I7/I6 -> 0 | J8: =J7/J6 -> 0 | ... O8: =O7/O6 -> 0.076415719
B10: 销量目标
B11: 销量完成
B12: 销量完成进度
B14: 实销目标
B15: 实销完成
B16: 实销完成进度
B18: GMV目标
B19: GMV完成
B20: GMV完成进度
B22: GSV目标
B23: GSV完成
B24: GSV完成进度
... B28: 利润率

Sheet 林梓蕾
A1: 2026年度WB进度
A2: 项目 | B2: 月度 | C2: 2月 | D2: 3月 | E2: 4月 | F2: 5月 | G2: 6月 | H2: 7月 | I2: 8月 | J2: 9月 | K2: 10月 | L2: 11月 | M2: 12月 | N2: 1月 | O2: 汇总
B3: 季度 | C3: Q1 | F3: Q2 | I3: Q3 | L3: Q4
B4: 季度财报 | C4: =(C7+D7+E7) -> 0 | F4: =(F7+G7+H7) -> 593668.09 | I4: =(I7+J7+K7) -> 0 | L4: =(L7+M7+N7) -> 0
B5: 季度财报进度 | C5: =(C7+D7+E7)/(C6+D6+E6) -> 0 | F5: =(F7+G7+H7)/(F6+G6+H6) -> 0.47759086 | I5: =(I7+J7+K7)/(I6+J6+K6) -> 0 | L5: =(L7+M7+N7)/(L6+M6+N6) -> 0
A6: 目标完成情况 | B6: 月度目标 利润（人民币） | C6: =[3]总目标!B44 -> 372843 | D6: =[3]总目标!C44 -> 566214.49 | E6: =[3]总目标!D44 -> 425981.19 | F6: =[3]总目标!E44 -> 428093.17 | G6: =[3]总目标!F44 -> 438328.65 | H6: =[3]总目标!G44 -> 376625.61 | I6: =[3]总目标!H44 -> 516638.6 | J6: =[3]总目标!I44 -> 499972.84 | ... N6: =[3]总目标!M44 -> 318392.87 | O6: =SUM(C6:N6) -> 5397380.4
B7: 实际利润（人民币） | C7: =[3]总目标!B45+[3]总目标!B46+[3]总目标!B47+[3]总目标!B48+[3]总目标!B49 -> 0 | D7: =[3]总目标!C45+[3]总目标!C46+[3]总目标!C47+[3]总目标!C48+[3]总目标!C49 -> 0 | E7: =[3]总目标!D45+[3]总目标!D46+[3]总目标!D47+[3]总目标!D48+[3]总目标!D49 -> 0 | F7: =[3]总目标!E45+[3]总目标!E46+[3]总目标!E47+[3]总目标!E48+[3]总目标!E49 -> 0 | G7: =[3]总目标!F45+[3]总目标!F46+[3]总目标!F47+[3]总目标!F48+[3]总目标!F49 -> 593668.09 | H7: =[3]总目标!G45+[3]总目标!G46+[3]总目标!G47+[3]总目标!G48+[3]总目标!G49 -> 0 | I7: =[3]总目标!H45+[3]总目标!H46+[3]总目标!H47+[3]总目标!H48+[3]总目标!H49 -> 0 | J7: =[3]总目标!I45+[3]总目标!I46+[3]总目标!I47+[3]总目标!I48+[3]总目标!I49 -> 0 | ... N7: =[3]总目标!M45+[3]总目标!M46+[3]总目标!M47+[3]总目标!M48+[3]总目标!M49 -> 0 | O7: =SUM(C7:N7) -> 593668.09
B8: 目标完成进度 | C8: =C7/C6 -> 0 | D8: =D7/D6 -> 0 | E8: =E7/E6 -> 0 | F8: =F7/F6 -> 0 | G8: =G7/G6 -> 1.3543903 | H8: =H7/H6 -> 0 | I8: =I7/I6 -> 0 | J8: =J7/J6 -> 0 | ... O8: =O7/O6 -> 0.10999189
B10: 销量目标
B11: 销量完成
B12: 销量完成进度
B14: 实销目标
B15: 实销完成
B16: 实销完成进度
B18: GMV目标
B19: GMV完成
B20: GMV完成进度
B22: GSV目标
B23: GSV完成
B24: GSV完成进度
... B28: 利润率

Sheet 陈敏华
A1: 2026年度WB进度
A2: 项目 | B2: 月度 | C2: 2月 | D2: 3月 | E2: 4月 | F2: 5月 | G2: 6月 | H2: 7月 | I2: 8月 | J2: 9月 | K2: 10月 | L2: 11月 | M2: 12月 | N2: 1月 | O2: 汇总
B3: 季度 | C3: Q1 | F3: Q2 | I3: Q3 | L3: Q4
B4: 季度财报 | C4: =(C7+D7+E7) -> 1368108.8 | F4: =(F7+G7+H7) -> 507178.22 | I4: =(I7+J7+K7) -> 0 | L4: =(L7+M7+N7) -> 0
B5: 季度财报进度 | C5: =(C7+D7+E7)/(C6+D6+E6) -> 0.92448405 | F5: =(F7+G7+H7)/(F6+G6+H6) -> 0.34069767 | I5: =(I7+J7+K7)/(I6+J6+K6) -> 0 | L5: =(L7+M7+N7)/(L6+M6+N6) -> 0
A6: 目标完成情况 | B6: 月度目标 利润（人民币） | C6: =[3]总目标!B58 -> 278839 | D6: =[3]总目标!C58 -> 672748.79 | E6: =[3]总目标!D58 -> 528274.18 | F6: =[3]总目标!E58 -> 526052.98 | G6: =[3]总目标!F58 -> 511352.46 | H6: =[3]总目标!G58 -> 451240.57 | I6: =[3]总目标!H58 -> 540132.31 | J6: =[3]总目标!I58 -> 525321.15 | ... N6: =[3]总目标!M58 -> 361615.51 | O6: =SUM(C6:N6) -> 5904690.5
B7: 实际利润（人民币） | C7: =[3]总目标!B59+[3]总目标!B60+[3]总目标!B61+[3]总目标!B62+[3]总目标!B63 -> 229311.59 | D7: =[3]总目标!C59+[3]总目标!C60+[3]总目标!C61+[3]总目标!C62+[3]总目标!C63 -> 770766.4 | E7: =[3]总目标!D59+[3]总目标!D60+[3]总目标!D61+[3]总目标!D62+[3]总目标!D63 -> 368030.79 | F7: =[3]总目标!E59+[3]总目标!E60+[3]总目标!E61+[3]总目标!E62+[3]总目标!E63 -> 363130.13 | G7: 144048.09 | H7: =[3]总目标!G59+[3]总目标!G60+[3]总目标!G61+[3]总目标!G62+[3]总目标!G63 -> 0 | I7: =[3]总目标!H59+[3]总目标!H60+[3]总目标!H61+[3]总目标!H62+[3]总目标!H63 -> 0 | J7: =[3]总目标!I59+[3]总目标!I60+[3]总目标!I61+[3]总目标!I62+[3]总目标!I63 -> 0 | K7: =[3]总目标!J59+[3]总目标!J60+[3]总目标!J61+[3]总目标!J62+[3]总目标!J63 -> 0 | L7: =[3]总目标!K59+[3]总目标!K60+[3]总目标!K61+[3]总目标!K62+[3]总目标!K63 -> 0 | M7: =[3]总目标!L59+[3]总目标!L60+[3]总目标!L61+[3]总目标!L62+[3]总目标!L63 -> 0 | N7: =[3]总目标!M59+[3]总目标!M60+[3]总目标!M61+[3]总目标!M62+[3]总目标!M63 -> 0 | O7: =SUM(C7:N7) -> 1875287
B8: 目标完成进度 | C8: =C7/C6 -> 0.8223799 | D8: =D7/D6 -> 1.1456972 | E8: =E7/E6 -> 0.69666625 | F8: =F7/F6 -> 0.69029194 | G8: =G7/G6 -> 0.2817002 | H8: =H7/H6 -> 0 | I8: =I7/I6 -> 0 | J8: =J7/J6 -> 0 | ... O8: =O7/O6 -> 0.31759277
B10: 销量目标
B11: 销量完成
B12: 销量完成进度
B14: 实销目标
B15: 实销完成
B16: 实销完成进度
B18: GMV目标
B19: GMV完成
B20: GMV完成进度
B22: GSV目标
B23: GSV完成
B24: GSV完成进度
... B28: 利润率

Sheet 包家豪
A1: 2026年度WB进度
A2: 项目 | B2: 月度 | C2: 2月 | D2: 3月 | E2: 4月 | F2: 5月 | G2: 6月 | H2: 7月 | I2: 8月 | J2: 9月 | K2: 10月 | L2: 11月 | M2: 12月 | N2: 1月 | O2: 汇总
B3: 季度 | C3: Q1 | F3: Q2 | I3: Q3 | L3: Q4
B4: 季度财报 | C4: =(C7+D7+E7) -> 66620.78 | F4: =(F7+G7+H7) -> 71602.76 | I4: =(I7+J7+K7) -> 0 | L4: =(L7+M7+N7) -> 0
B5: 季度财报进度 | C5: =(C7+D7+E7)/(C6+D6+E6) -> 0.26102544 | F5: =(F7+G7+H7)/(F6+G6+H6) -> 0.1454621 | I5: =(I7+J7+K7)/(I6+J6+K6) -> 0 | L5: =(L7+M7+N7)/(L6+M6+N6) -> 0
A6: 目标完成情况 | B6: 月度目标 利润（人民币） | C6: =[3]总目标!B70 -> 34481 | D6: =[3]总目标!C70 -> 86791.297 | E6: =[3]总目标!D70 -> 133954.86 | F6: =[3]总目标!E70 -> 141243.46 | G6: =[3]总目标!F70 -> 195306.82 | H6: =[3]总目标!G70 -> 155693.13 | I6: =[3]总目标!H70 -> 213216.28 | J6: =[3]总目标!I70 -> 206338.34 | ... N6: =[3]总目标!M70 -> 98770.51 | O6: =SUM(C6:N6) -> 1844131.2
B7: 实际利润（人民币） | C7: =[3]总目标!B71+[3]总目标!B72+[3]总目标!B73+[3]总目标!B74+[3]总目标!B75 -> 0 | D7: =[3]总目标!C71+[3]总目标!C72+[3]总目标!C73+[3]总目标!C74+[3]总目标!C75 -> 52452.23 | E7: =[3]总目标!D71+[3]总目标!D72+[3]总目标!D73+[3]总目标!D74+[3]总目标!D75 -> 14168.55 | F7: =[3]总目标!E71+[3]总目标!E72+[3]总目标!E73+[3]总目标!E74+[3]总目标!E75 -> 49822.88 | G7: 21779.88 | H7: =[3]总目标!G71+[3]总目标!G72+[3]总目标!G73+[3]总目标!G74+[3]总目标!G75 -> 0 | I7: =[3]总目标!H71+[3]总目标!H72+[3]总目标!H73+[3]总目标!H74+[3]总目标!H75 -> 0 | J7: =[3]总目标!I71+[3]总目标!I72+[3]总目标!I73+[3]总目标!I74+[3]总目标!I75 -> 0 | K7: =[3]总目标!J71+[3]总目标!J72+[3]总目标!J73+[3]总目标!J74+[3]总目标!J75 -> 0 | L7: =[3]总目标!K71+[3]总目标!K72+[3]总目标!K73+[3]总目标!K74+[3]总目标!K75 -> 0 | M7: =[3]总目标!L71+[3]总目标!L72+[3]总目标!L73+[3]总目标!L74+[3]总目标!L75 -> 0 | N7: =[3]总目标!M71+[3]总目标!M72+[3]总目标!M73+[3]总目标!M74+[3]总目标!M75 -> 0 | O7: =SUM(C7:N7) -> 138223.54
B8: 目标完成进度 | C8: =C7/C6 -> 0 | D8: =D7/D6 -> 0.60434896 | E8: =E7/E6 -> 0.10577108 | F8: =F7/F6 -> 0.35274468 | G8: =G7/G6 -> 0.11151623 | H8: =H7/H6 -> 0 | I8: =I7/I6 -> 0 | J8: =J7/J6 -> 0 | ... O8: =O7/O6 -> 0.074953203
B10: 销量目标
B11: 销量完成
B12: 销量完成进度
B14: 实销目标
B15: 实销完成
B16: 实销完成进度
B18: GMV目标
B19: GMV完成
B20: GMV完成进度
B22: GSV目标
B23: GSV完成
B24: GSV完成进度
... B28: 利润率
